Workbook

Sheet README
A1: Skill 快速验证流水线 · 台账工作簿
A3: 生成方式 | B3: .skills/anthropic-skills/skills/xlsx（anthropics/skills）+ openpyxl 3.1.5；脚本 build_xlsx.py
A4: 数据口径 | B4: Run Ledger!F 主产物字节＝stat -f%z 实测；K/L 日志 PASS/FAIL 标记数＝grep -c 实测（含中途被推翻的假 FAIL）；H 耗时秒取自 state.json runs[].seconds
A5: 编辑指引 | B5: 只有蓝色（F/H/K/L/O）与黄色底纹单元格是输入，其余黑色公式与绿色跨表引用请保持不动；改输入后整表自动重算
A6: 公式约定 | B6: 只用 Excel-2007 时代函数（SUM/SUMIFS/COUNTIF/AVERAGEIF/INDEX/MATCH/IFERROR/MAX/MIN/ROUND），不用 XLOOKUP/FILTER/SORT/UNIQUE，不加 _xlfn 前缀函数
A7: 本机限制 | B7: 技能自带的 scripts/recalc.py 需要 LibreOffice，本机无 soffice；本文件公式值由纯 Python 引擎 formulas 1.3.4 独立重算核对（见 verify_recalc.py 与 output.log）
A9: 图例
A10: 蓝色字体 = 硬编码输入
A11: 黑色字体 = 公式
A12: 绿色字体 = 跨表链接
A13: 黄色底纹 = 本工作簿留给读者的待填假设格 | B13: 900 | C13: 预算基准（秒/轮）；来源：本任务提示词「15 分钟内出产物」= 900 秒
A15: 示例行（真实数据，展示格式） | B15: 2026-09-26 | C15: 1140 | D15: =C15/60 | E15: 0.2

Sheet Ledger
A1: 轮次 | B1: 日期 | C1: 技能 | D1: 来源 | E1: 产物类别 | F1: 主产物 (B) | G1: 主产物 (KB) | H1: 耗时 (s) | I1: 耗时 (min) | J1: B/s | K1: 日志 PASS 标记 | L1: 日志 FAIL 标记 | M1: 验证标记合计 | N1: PASS 占比 | O1: 本轮新装技能 | P1: 结论 | Q1: 主产物路径
A2: 1 | B2: 2026-09-25 | C2: drafter | D2: 官方市场 | E2: 工程图纸 HTML | F2: 15146 | G2: =F2/1024 | H2: 420 | I2: =IF(H2="","",H2/60) | J2: =IFERROR(F2/H2,"") | K2: 34 | L2: 4 | M2: =K2+L2 | N2: =IFERROR(K2/M2,"") | O2: 1 | P2: 留用 | Q2: demos/20260925-1723-drafter/skill-lab-pipeline-blueprint.html
A3: 2 | B3: 2026-09-25 | C3: ascii-project-dashboard | D3: 官方市场 | E3: 终端 ASCII 看板 | F3: 2846 | G3: =F3/1024 | H3: 600 | I3: =IF(H3="","",H3/60) | J3: =IFERROR(F3/H3,"") | K3: 20 | L3: 6 | M3: =K3+L3 | N3: =IFERROR(K3/M3,"") | O3: 1 | P3: 留用 | Q3: demos/20260925-1737-ascii-project-dashboard/dashboard.txt
A4: 3 | B4: 2026-09-25 | C4: algorithmic-art | D4: 外部仓库 | E4: 生成艺术 HTML | F4: 998549 | G4: =F4/1024 | H4: 1140 | I4: =IF(H4="","",H4/60) | J4: =IFERROR(F4/H4,"") | K4: 20 | L4: 0 | M4: =K4+L4 | N4: =IFERROR(K4/M4,"") | O4: 0 | P4: 留用 | Q4: demos/20260925-1810-algorithmic-art/art-index.html
A5: 4 | B5: 2026-09-25 | C5: SQLite-Database-Expert | D5: 本机已装 | E5: SQLite 检索库 | F5: 299008 | G5: =F5/1024 | H5: 780 | I5: =IF(H5="","",H5/60) | J5: =IFERROR(F5/H5,"") | K5: 14 | L5: 1 | M5: =K5+L5 | N5: =IFERROR(K5/M5,"") | O5: 0 | P5: 留用 | Q5: demos/20260925-1845-sqlite-database-expert/lab.db
A6: 5 | B6: 2026-09-25 | C6: ppt-generator | D6: 官方市场 | E6: 幻灯片 PPTX | F6: 48873 | G6: =F6/1024 | H6: 600 | I6: =IF(H6="","",H6/60) | J6: =IFERROR(F6/H6,"") | K6: 14 | L6: 0 | M6: =K6+L6 | N6: =IFERROR(K6/M6,"") | O6: 1 | P6: 留用 | Q6: demos/20260925-1906-ppt-generator/skill-showcase-pixel-retro.pptx
A7: 6 | B7: 2026-09-25 | C7: graphic-gif | D7: 官方市场 | E7: 动画 GIF | F7: 48293 | G7: =F7/1024 | H7: 900 | I7: =IF(H7="","",H7/60) | J7: =IFERROR(F7/H7,"") | K7: 27 | L7: 1 | M7: =K7+L7 | N7: =IFERROR(K7/M7,"") | O7: 1 | P7: 留用 | Q7: demos/20260925-1950-graphic-gif/animation.gif
A8: 7 | B8: 2026-09-25 | C8: build-game | D8: 官方市场 | E8: 3D 游戏 HTML | F8: 750620 | G8: =F8/1024 | H8: 1440 | I8: =IF(H8="","",H8/60) | J8: =IFERROR(F8/H8,"") | K8: 24 | L8: 1 | M8: =K8+L8 | N8: =IFERROR(K8/M8,"") | O8: 1 | P8: 留用·强推荐 | Q8: demos/20260925-2332-build-game/frostlight-gather.html
A9: 8 | B9: 2026-09-26 | C9: sec-audit-cn | D9: 本机已装 | E9: 审计报告 MD | F9: 11247 | G9: =F9/1024 | I9: =IF(H9="","",H9/60) | J9: =IFERROR(F9/H9,"") | K9: 0 | L9: 0 | M9: =K9+L9 | N9: =IFERROR(K9/M9,"") | O9: 0 | P9: 留用 | Q9: demos/20260926-0000-sec-audit-cn/SECURITY-AUDIT.md

Sheet Metrics
A1: 流水线指标看板（全部为公式，随 Ledger 输入自动重算）
A2: 蓝色格为唯一手工输入（README!B13 预算基准）；本表无一处硬编码统计值。
A4: 指标 | B4: 值 | C4: 公式口径（本表所有值均为公式，无一硬编码）
A5: ■ 总量
A6: 已完成轮次 | B6: =COUNT(Ledger!$A$2:$A$9) | C6: =COUNT(Ledger!$A$2:$A$9)
A7: 主产物合计 (B) | B7: =SUM(Ledger!$F$2:$F$9) | C7: =SUM(Ledger!$F$2:$F$9)
A8: 主产物合计 (KB) | B8: =SUM(Ledger!$F$2:$F$9)/1024 | C8: =SUM(Ledger!$F$2:$F$9)/1024
A9: 单轮平均产物 (KB) | B9: =AVERAGE(Ledger!$G$2:$G$9) | C9: =AVERAGE(Ledger!$G$2:$G$9)
A10: 最大单产物 (KB) | B10: =MAX(Ledger!$G$2:$G$9) | C10: =MAX(Ledger!$G$2:$G$9)
A11: 最大单产物所属技能 | B11: =INDEX(Ledger!$C$2:$C$9,MATCH(MAX(Ledger!$F$2:$F$9),Ledger!$F$2:$F$9,0)) | C11: =INDEX(Ledger!$C$2:$C$9,MATCH(MAX(Ledger!$F$2:$F$9),Ledger!$F$2:$F$9,0))
A12: 最小单产物所属技能 | B12: =INDEX(Ledger!$C$2:$C$9,MATCH(MIN(Ledger!$F$2:$F$9),Ledger!$F$2:$F$9,0)) | C12: =INDEX(Ledger!$C$2:$C$9,MATCH(MIN(Ledger!$F$2:$F$9),Ledger!$F$2:$F$9,0))
A13: ■ 耗时与预算
A14: 有耗时记录轮次 | B14: =COUNT(Ledger!$H$2:$H$9) | C14: =COUNT(Ledger!$H$2:$H$9)
A15: 累计耗时 (min) | B15: =SUM(Ledger!$H$2:$H$9)/60 | C15: =SUM(Ledger!$H$2:$H$9)/60
A16: 平均单轮耗时 (min) | B16: =IFERROR(SUM(Ledger!$H$2:$H$9)/COUNT(Ledger!$H$2:$H$9)/60,"") | C16: =IFERROR(SUM(Ledger!$H$2:$H$9)/COUNT(Ledger!$H$2:$H$9)/60,"")
A17: 超预算轮数 (>预算基准) | B17: =COUNTIF(Ledger!$H$2:$H$9,">"&README!$B$13) | C17: =COUNTIF(Ledger!$H$2:$H$9,">"&README!$B$13)
A18: 预算基准 (s) | B18: =README!$B$13 | C18: =README!$B$13
A19: 预算利用率 | B19: =IFERROR(SUM(Ledger!$H$2:$H$9)/(COUNT(Ledger!$H$2:$H$9)*README!$B$13),"") | C19: =IFERROR(SUM(Ledger!$H$2:$H$9)/(COUNT(Ledger!$H$2:$H$9)*README!$B$13),"")
A20: 最慢轮次技能 | B20: =INDEX(Ledger!$C$2:$C$9,MATCH(MAX(Ledger!$H$2:$H$9),Ledger!$H$2:$H$9,0)) | C20: =INDEX(Ledger!$C$2:$C$9,MATCH(MAX(Ledger!$H$2:$H$9),Ledger!$H$2:$H$9,0))
A21: ■ 验证强度
A22: 验证标记合计 | B22: =SUM(Ledger!$M$2:$M$9) | C22: =SUM(Ledger!$M$2:$M$9)
A23: PASS 标记合计 | B23: =SUM(Ledger!$K$2:$K$9) | C23: =SUM(Ledger!$K$2:$K$9)
A24: FAIL 标记合计 | B24: =SUM(Ledger!$L$2:$L$9) | C24: =SUM(Ledger!$L$2:$L$9)
A25: 总体 PASS 占比 | B25: =IFERROR(SUM(Ledger!$K$2:$K$9)/SUM(Ledger!$M$2:$M$9),"") | C25: =IFERROR(SUM(Ledger!$K$2:$K$9)/SUM(Ledger!$M$2:$M$9),"")
A26: 每千 KB 产物验证标记 | B26: =IFERROR(SUM(Ledger!$M$2:$M$9)/(SUM(Ledger!$F$2:$F$9)/1024),"") | C26: =IFERROR(SUM(Ledger!$M$2:$M$9)/(SUM(Ledger!$F$2:$F$9)/1024),"")
A27: 最高 PASS 占比轮次技能 | B27: =INDEX(Ledger!$C$2:$C$9,MATCH(MAX(Ledger!$N$2:$N$9),Ledger!$N$2:$N$9,0)) | C27: =INDEX(Ledger!$C$2:$C$9,MATCH(MAX(Ledger!$N$2:$N$9),Ledger!$N$2:$N$9,0))
A28: ■ 来源结构
A29: 分组 | B29: 轮次数 | C29: 产物合计 (KB) | D29: 平均耗时 (min)
A30: 官方市场 | B30: =COUNTIF(Ledger!$D$2:$D$9,$A$30) | C30: =SUMIF(Ledger!$D$2:$D$9,$A$30,Ledger!$F$2:$F$9)/1024 | D30: =IFERROR(SUMIF(Ledger!$D$2:$D$9,$A$30,Ledger!$H$2:$H$9)/COUNTIFS(Ledger!$D$2:$D$9,$A$30,Ledger!$H$2:$H$9,">0")/60,"")
A31: 外部仓库 | B31: =COUNTIF(Ledger!$D$2:$D$9,$A$31) | C31: =SUMIF(Ledger!$D$2:$D$9,$A$31,Ledger!$F$2:$F$9)/1024 | D31: =IFERROR(SUMIF(Ledger!$D$2:$D$9,$A$31,Ledger!$H$2:$H$9)/COUNTIFS(Ledger!$D$2:$D$9,$A$31,Ledger!$H$2:$H$9,">0")/60,"")
A32: 本机已装 | B32: =COUNTIF(Ledger!$D$2:$D$9,$A$32) | C32: =SUMIF(Ledger!$D$2:$D$9,$A$32,Ledger!$F$2:$F$9)/1024 | D32: =IFERROR(SUMIF(Ledger!$D$2:$D$9,$A$32,Ledger!$H$2:$H$9)/COUNTIFS(Ledger!$D$2:$D$9,$A$32,Ledger!$H$2:$H$9,">0")/60,"")
A33: ■ 产物类别多样性
A34: 分组 | B34: 轮次数 | C34: 产物合计 (KB) | D34: 平均耗时 (min)
A35: 工程图纸 HTML | B35: =COUNTIF(Ledger!$E$2:$E$9,$A$35) | C35: =SUMIF(Ledger!$E$2:$E$9,$A$35,Ledger!$F$2:$F$9)/1024 | D35: =IFERROR(SUMIF(Ledger!$E$2:$E$9,$A$35,Ledger!$H$2:$H$9)/COUNTIFS(Ledger!$E$2:$E$9,$A$35,Ledger!$H$2:$H$9,">0")/60,"")
A36: 终端 ASCII 看板 | B36: =COUNTIF(Ledger!$E$2:$E$9,$A$36) | C36: =SUMIF(Ledger!$E$2:$E$9,$A$36,Ledger!$F$2:$F$9)/1024 | D36: =IFERROR(SUMIF(Ledger!$E$2:$E$9,$A$36,Ledger!$H$2:$H$9)/COUNTIFS(Ledger!$E$2:$E$9,$A$36,Ledger!$H$2:$H$9,">0")/60,"")
A37: 生成艺术 HTML | B37: =COUNTIF(Ledger!$E$2:$E$9,$A$37) | C37: =SUMIF(Ledger!$E$2:$E$9,$A$37,Ledger!$F$2:$F$9)/1024 | D37: =IFERROR(SUMIF(Ledger!$E$2:$E$9,$A$37,Ledger!$H$2:$H$9)/COUNTIFS(Ledger!$E$2:$E$9,$A$37,Ledger!$H$2:$H$9,">0")/60,"")
A38: SQLite 检索库 | B38: =COUNTIF(Ledger!$E$2:$E$9,$A$38) | C38: =SUMIF(Ledger!$E$2:$E$9,$A$38,Ledger!$F$2:$F$9)/1024 | D38: =IFERROR(SUMIF(Ledger!$E$2:$E$9,$A$38,Ledger!$H$2:$H$9)/COUNTIFS(Ledger!$E$2:$E$9,$A$38,Ledger!$H$2:$H$9,">0")/60,"")
A39: 幻灯片 PPTX | B39: =COUNTIF(Ledger!$E$2:$E$9,$A$39) | C39: =SUMIF(Ledger!$E$2:$E$9,$A$39,Ledger!$F$2:$F$9)/1024 | D39: =IFERROR(SUMIF(Ledger!$E$2:$E$9,$A$39,Ledger!$H$2:$H$9)/COUNTIFS(Ledger!$E$2:$E$9,$A$39,Ledger!$H$2:$H$9,">0")/60,"")
A40: 动画 GIF | B40: =COUNTIF(Ledger!$E$2:$E$9,$A$40) | C40: =SUMIF(Ledger!$E$2:$E$9,$A$40,Ledger!$F$2:$F$9)/1024 | D40: =IFERROR(SUMIF(Ledger!$E$2:$E$9,$A$40,Ledger!$H$2:$H$9)/COUNTIFS(Ledger!$E$2:$E$9,$A$40,Ledger!$H$2:$H$9,">0")/60,"")
A41: 3D 游戏 HTML | B41: =COUNTIF(Ledger!$E$2:$E$9,$A$41) | C41: =SUMIF(Ledger!$E$2:$E$9,$A$41,Ledger!$F$2:$F$9)/1024 | D41: =IFERROR(SUMIF(Ledger!$E$2:$E$9,$A$41,Ledger!$H$2:$H$9)/COUNTIFS(Ledger!$E$2:$E$9,$A$41,Ledger!$H$2:$H$9,">0")/60,"")
...
